[INFO]: Run Directory: /workspace/digital/designs/Radio/runs/RUN_2025.06.26_05.40.44
[INFO]: Saving runtime environment...
[INFO]: Preparing LEF files for the nom corner...
[INFO]: Preparing LEF files for the min corner...
[INFO]: Preparing LEF files for the max corner...
[WARNING]: PNR_SDC_FILE is not set. It is recommended to write a custom SDC file for the design. Defaulting to BASE_SDC_FILE
[WARNING]: SIGNOFF_SDC_FILE is not set. It is recommended to write a custom SDC file for the design. Defaulting to BASE_SDC_FILE
[INFO]: Running linter (Verilator) (log: digital/designs/Radio/runs/RUN_2025.06.26_05.40.44/logs/synthesis/linter.log)...
[ERROR]: 3 errors found by linter
[ERROR]: Step 0 (verilator_lint_check) failed with error:
-code 1 -level 0 -errorstack {INNER {invokeStk1 throw_error} CALL run_verilator CALL run_verilator_step CALL {run_non_interactive_mode -design /workspace/digital/designs/Radio/}} -errorcode NONE -errorinfo {
    while executing
"throw_error"
    (procedure "run_verilator" line 86)
    invoked from within
"run_verilator"
    (procedure "run_verilator_step" line 3)
    invoked from within
"run_verilator_step"} -errorline 1
[INFO]: Saving current set of views in 'digital/designs/Radio/runs/RUN_2025.06.26_05.40.44/results/final'...
[INFO]: Generating final set of reports...
[ERROR]: Failed to create manufacturability and metric reports:
[ERROR]: Traceback (most recent call last):
  File "/nix/store/xpc7xd67rslanlqh566s6jph53bn830w-openlane1-1.1.1/bin/scripts/generate_reports.py", line 184, in <module>
    cli()
  File "/nix/store/8ywrzlq8yyqrif2sfvbgg8vsxhj80ry7-python3-3.11.9-env/lib/python3.11/site-packages/click/core.py", line 1157, in __call__
    return self.main(*args, **kwargs)
           ^^^^^^^^^^^^^^^^^^^^^^^^^^
  File "/nix/store/8ywrzlq8yyqrif2sfvbgg8vsxhj80ry7-python3-3.11.9-env/lib/python3.11/site-packages/click/core.py", line 1078, in main
    rv = self.invoke(ctx)
         ^^^^^^^^^^^^^^^^
  File "/nix/store/8ywrzlq8yyqrif2sfvbgg8vsxhj80ry7-python3-3.11.9-env/lib/python3.11/site-packages/click/core.py", line 1434, in invoke
    return ctx.invoke(self.callback, **ctx.params)
           ^^^^^^^^^^^^^^^^^^^^^^^^^^^^^^^^^^^^^^^
  File "/nix/store/8ywrzlq8yyqrif2sfvbgg8vsxhj80ry7-python3-3.11.9-env/lib/python3.11/site-packages/click/core.py", line 783, in invoke
    return __callback(*args, **kwargs)
           ^^^^^^^^^^^^^^^^^^^^^^^^^^^
  File "/nix/store/xpc7xd67rslanlqh566s6jph53bn830w-openlane1-1.1.1/bin/scripts/generate_reports.py", line 51, in cli
    report = Report(design, tag, design_name, params, run_path).get_report()
             ^^^^^^^^^^^^^^^^^^^^^^^^^^^^^^^^^^^^^^^^^^^^^^^^^^^^^^^^^^^^^^^
  File "/nix/store/xpc7xd67rslanlqh566s6jph53bn830w-openlane1-1.1.1/bin/scripts/report/report.py", line 809, in get_report
    *self.extract_all_values(),
     ^^^^^^^^^^^^^^^^^^^^^^^^^
  File "/nix/store/xpc7xd67rslanlqh566s6jph53bn830w-openlane1-1.1.1/bin/scripts/report/report.py", line 359, in extract_all_values
    power_report = Artifact(
                   ^^^^^^^^^
  File "/nix/store/xpc7xd67rslanlqh566s6jph53bn830w-openlane1-1.1.1/bin/scripts/report/report.py", line 62, in __init__
    self.pathname = matches[0]
                    ~~~~~~~^^^
IndexError: list index out of range
[INFO]: Saving runtime environment...
[ERROR]: Flow failed.
[INFO]: The failure may have been because of the following warnings:
